2019-02-06 19:53:20 [scrapy.utils.log] INFO: Scrapy 1.5.0 started (bot: meinr)
2019-02-06 19:53:20 [scrapy.utils.log] INFO: Versions: lxml 4.1.1.0, libxml2 2.9.5, cssselect 1.0.3, parsel 1.3.1, w3lib 1.18.0, Twisted 18.9.0, Python 3.6.0 (v3.6.0:41df79263a11, Dec 23 2016, 08:06:12) [MSC v.1900 64 bit (AMD64)], pyOpenSSL 17.5.0 (OpenSSL 1.1.0h  27 Mar 2018), cryptography 2.3, Platform Windows-7-6.1.7601-SP1
2019-02-06 19:53:20 [scrapy.crawler] INFO: Overridden settings: {'BOT_NAME': 'meinr', 'LOG_FILE': 'logs\\2019_02_19_53_20_meinr.log', 'LOG_LEVEL': 'INFO', 'NEWSPIDER_MODULE': 'meinr.spiders', 'SPIDER_MODULES': ['meinr.spiders']}
2019-02-06 19:53:20 [scrapy.middleware] INFO: Enabled extensions:
['scrapy.extensions.corestats.CoreStats',
 'scrapy.extensions.telnet.TelnetConsole',
 'scrapy.extensions.logstats.LogStats']
2019-02-06 19:53:20 [py.warnings] WARNING: D:\spider_git\meinr\meinr\middlewares.py:10: ScrapyDeprecationWarning: Module `scrapy.contrib.downloadermiddleware.useragent` is deprecated, use `scrapy.downloadermiddlewares.useragent` instead
  from scrapy.contrib.downloadermiddleware.useragent import UserAgentMiddleware

2019-02-06 19:53:21 [scrapy.middleware] INFO: Enabled downloader middlewares:
['scrapy.downloadermiddlewares.httpauth.HttpAuthMiddleware',
 'meinr.middlewares.UserAgentMiddleware',
 'scrapy.downloadermiddlewares.downloadtimeout.DownloadTimeoutMiddleware',
 'scrapy.downloadermiddlewares.defaultheaders.DefaultHeadersMiddleware',
 'scrapy.downloadermiddlewares.useragent.UserAgentMiddleware',
 'meinr.middlewares.MeinrDownloaderMiddleware',
 'scrapy.downloadermiddlewares.retry.RetryMiddleware',
 'scrapy.downloadermiddlewares.redirect.MetaRefreshMiddleware',
 'scrapy.downloadermiddlewares.httpcompression.HttpCompressionMiddleware',
 'scrapy.downloadermiddlewares.redirect.RedirectMiddleware',
 'scrapy.downloadermiddlewares.cookies.CookiesMiddleware',
 'scrapy.downloadermiddlewares.httpproxy.HttpProxyMiddleware',
 'scrapy.downloadermiddlewares.stats.DownloaderStats']
2019-02-06 19:53:21 [scrapy.middleware] INFO: Enabled spider middlewares:
['scrapy.spidermiddlewares.httperror.HttpErrorMiddleware',
 'scrapy.spidermiddlewares.offsite.OffsiteMiddleware',
 'scrapy.spidermiddlewares.referer.RefererMiddleware',
 'scrapy.spidermiddlewares.urllength.UrlLengthMiddleware',
 'scrapy.spidermiddlewares.depth.DepthMiddleware']
2019-02-06 19:53:21 [scrapy.middleware] INFO: Enabled item pipelines:
['meinr.pipelines.MeinrPipeline']
2019-02-06 19:53:21 [scrapy.core.engine] INFO: Spider opened
2019-02-06 19:53:21 [scrapy.extensions.logstats] INFO: Crawled 0 pages (at 0 pages/min), scraped 0 items (at 0 items/min)
2019-02-06 19:53:21 [meinr1] INFO: Spider opened: meinr1
2019-02-06 19:53:36 [scrapy.spidermiddlewares.httperror] INFO: Ignoring response <404 http://m.tupianzj.com/meinv/20170228/89206_1.html>: HTTP status code is not handled or not allowed
2019-02-06 19:53:44 [scrapy.spidermiddlewares.httperror] INFO: Ignoring response <404 http://m.tupianzj.com/meinv/20170603/124213_1.html>: HTTP status code is not handled or not allowed
2019-02-06 19:53:46 [scrapy.spidermiddlewares.httperror] INFO: Ignoring response <404 http://m.tupianzj.com/meinv/20180203/155848_1.html>: HTTP status code is not handled or not allowed
2019-02-06 19:53:48 [scrapy.spidermiddlewares.httperror] INFO: Ignoring response <404 http://m.tupianzj.com/meinv/20180225/156249_1.html>: HTTP status code is not handled or not allowed
2019-02-06 19:53:57 [scrapy.spidermiddlewares.httperror] INFO: Ignoring response <404 http://m.tupianzj.com/meinv/20180226/156256_1.html>: HTTP status code is not handled or not allowed
2019-02-06 19:54:18 [scrapy.spidermiddlewares.httperror] INFO: Ignoring response <404 http://m.tupianzj.com/meinv/20180225/156254_1.html>: HTTP status code is not handled or not allowed
2019-02-06 19:54:18 [scrapy.spidermiddlewares.httperror] INFO: Ignoring response <404 http://m.tupianzj.com/meinv/20170225/88805_1.html>: HTTP status code is not handled or not allowed
2019-02-06 19:54:19 [scrapy.spidermiddlewares.httperror] INFO: Ignoring response <404 http://m.tupianzj.com/meinv/20160914/63887_1.html>: HTTP status code is not handled or not allowed
2019-02-06 19:54:29 [scrapy.extensions.logstats] INFO: Crawled 139 pages (at 139 pages/min), scraped 56 items (at 56 items/min)
2019-02-06 19:54:31 [scrapy.spidermiddlewares.httperror] INFO: Ignoring response <404 http://m.tupianzj.com/meinv/20181106/172969_1.html>: HTTP status code is not handled or not allowed
2019-02-06 19:54:35 [scrapy.spidermiddlewares.httperror] INFO: Ignoring response <404 http://m.tupianzj.com/meinv/20180102/153205_1.html>: HTTP status code is not handled or not allowed
2019-02-06 19:54:37 [scrapy.spidermiddlewares.httperror] INFO: Ignoring response <404 http://m.tupianzj.com/meinv/20181106/172962_1.html>: HTTP status code is not handled or not allowed
2019-02-06 19:54:39 [scrapy.spidermiddlewares.httperror] INFO: Ignoring response <404 http://m.tupianzj.com/meinv/20150924/27215_1.html>: HTTP status code is not handled or not allowed
2019-02-06 19:54:39 [scrapy.spidermiddlewares.httperror] INFO: Ignoring response <404 http://m.tupianzj.com/meinv/20160929/65280_1.html>: HTTP status code is not handled or not allowed
2019-02-06 19:54:39 [scrapy.spidermiddlewares.httperror] INFO: Ignoring response <404 http://m.tupianzj.com/meinv/20160830/62374_1.html>: HTTP status code is not handled or not allowed
2019-02-06 19:54:41 [scrapy.spidermiddlewares.httperror] INFO: Ignoring response <404 http://m.tupianzj.com/meinv/20150826/23850_1.html>: HTTP status code is not handled or not allowed
2019-02-06 19:54:41 [scrapy.spidermiddlewares.httperror] INFO: Ignoring response <404 http://m.tupianzj.com/meinv/20180225/156252_1.html>: HTTP status code is not handled or not allowed
2019-02-06 19:54:43 [scrapy.spidermiddlewares.httperror] INFO: Ignoring response <404 http://m.tupianzj.com/meinv/20140612/10694_1.html>: HTTP status code is not handled or not allowed
2019-02-06 19:54:44 [scrapy.spidermiddlewares.httperror] INFO: Ignoring response <404 http://m.tupianzj.com/meinv/20180225/156250_1.html>: HTTP status code is not handled or not allowed
2019-02-06 19:54:44 [scrapy.spidermiddlewares.httperror] INFO: Ignoring response <404 http://m.tupianzj.com/meinv/20180225/156248_1.html>: HTTP status code is not handled or not allowed
2019-02-06 19:54:46 [scrapy.spidermiddlewares.httperror] INFO: Ignoring response <404 http://m.tupianzj.com/meinv/20170225/88728_1.html>: HTTP status code is not handled or not allowed
2019-02-06 19:54:49 [scrapy.spidermiddlewares.httperror] INFO: Ignoring response <404 http://m.tupianzj.com/meinv/20170225/88701_1.html>: HTTP status code is not handled or not allowed
2019-02-06 19:54:58 [scrapy.spidermiddlewares.httperror] INFO: Ignoring response <404 http://m.tupianzj.com/meinv/20180130/155586_1.html>: HTTP status code is not handled or not allowed
2019-02-06 19:54:58 [scrapy.spidermiddlewares.httperror] INFO: Ignoring response <404 http://m.tupianzj.com/meinv/20170221/87980_1.html>: HTTP status code is not handled or not allowed
2019-02-06 19:55:00 [scrapy.spidermiddlewares.httperror] INFO: Ignoring response <404 http://m.tupianzj.com/meinv/20180130/155588_1.html>: HTTP status code is not handled or not allowed
2019-02-06 19:55:07 [scrapy.spidermiddlewares.httperror] INFO: Ignoring response <404 http://m.tupianzj.com/meinv/20170228/89207_1.html>: HTTP status code is not handled or not allowed
2019-02-06 19:55:11 [scrapy.spidermiddlewares.httperror] INFO: Ignoring response <404 http://m.tupianzj.com/meinv/20170227/89086_1.html>: HTTP status code is not handled or not allowed
2019-02-06 19:55:18 [scrapy.spidermiddlewares.httperror] INFO: Ignoring response <404 http://m.tupianzj.com/meinv/20170227/89091_1.html>: HTTP status code is not handled or not allowed
2019-02-06 19:55:22 [scrapy.spidermiddlewares.httperror] INFO: Ignoring response <404 http://m.tupianzj.com/meinv/20180203/155854_1.html>: HTTP status code is not handled or not allowed
2019-02-06 19:55:22 [scrapy.extensions.logstats] INFO: Crawled 260 pages (at 121 pages/min), scraped 149 items (at 93 items/min)
2019-02-06 19:55:46 [scrapy.core.scraper] ERROR: Error processing {'img': 'http://img.tupianzj.com/uploads/allimg/180203/9-1P203130U6.jpg',
 'num': 8,
 'title': '美女模特Yumi尤美连体比基尼妩媚写真'}
Traceback (most recent call last):
  File "D:\Python\Python36\lib\site-packages\urllib3\connectionpool.py", line 601, in urlopen
    chunked=chunked)
  File "D:\Python\Python36\lib\site-packages\urllib3\connectionpool.py", line 387, in _make_request
    six.raise_from(e, None)
  File "<string>", line 2, in raise_from
  File "D:\Python\Python36\lib\site-packages\urllib3\connectionpool.py", line 383, in _make_request
    httplib_response = conn.getresponse()
  File "D:\Python\Python36\lib\http\client.py", line 1331, in getresponse
    response.begin()
  File "D:\Python\Python36\lib\http\client.py", line 297, in begin
    version, status, reason = self._read_status()
  File "D:\Python\Python36\lib\http\client.py", line 258, in _read_status
    line = str(self.fp.readline(_MAXLINE + 1), "iso-8859-1")
  File "D:\Python\Python36\lib\socket.py", line 586, in readinto
    return self._sock.recv_into(b)
TimeoutError: [WinError 10060] 由于连接方在一段时间后没有正确答复或连接的主机没有反应，连接尝试失败。

During handling of the above exception, another exception occurred:

Traceback (most recent call last):
  File "D:\Python\Python36\lib\site-packages\requests\adapters.py", line 440, in send
    timeout=timeout
  File "D:\Python\Python36\lib\site-packages\urllib3\connectionpool.py", line 639, in urlopen
    _stacktrace=sys.exc_info()[2])
  File "D:\Python\Python36\lib\site-packages\urllib3\util\retry.py", line 357, in increment
    raise six.reraise(type(error), error, _stacktrace)
  File "D:\Python\Python36\lib\site-packages\urllib3\packages\six.py", line 685, in reraise
    raise value.with_traceback(tb)
  File "D:\Python\Python36\lib\site-packages\urllib3\connectionpool.py", line 601, in urlopen
    chunked=chunked)
  File "D:\Python\Python36\lib\site-packages\urllib3\connectionpool.py", line 387, in _make_request
    six.raise_from(e, None)
  File "<string>", line 2, in raise_from
  File "D:\Python\Python36\lib\site-packages\urllib3\connectionpool.py", line 383, in _make_request
    httplib_response = conn.getresponse()
  File "D:\Python\Python36\lib\http\client.py", line 1331, in getresponse
    response.begin()
  File "D:\Python\Python36\lib\http\client.py", line 297, in begin
    version, status, reason = self._read_status()
  File "D:\Python\Python36\lib\http\client.py", line 258, in _read_status
    line = str(self.fp.readline(_MAXLINE + 1), "iso-8859-1")
  File "D:\Python\Python36\lib\socket.py", line 586, in readinto
    return self._sock.recv_into(b)
urllib3.exceptions.ProtocolError: ('Connection aborted.', TimeoutError(10060, '由于连接方在一段时间后没有正确答复或连接的主机没有反应，连接尝试失败。', None, 10060, None))

During handling of the above exception, another exception occurred:

Traceback (most recent call last):
  File "D:\Python\Python36\lib\site-packages\twisted\internet\defer.py", line 654, in _runCallbacks
    current.result = callback(current.result, *args, **kw)
  File "D:\spider_git\meinr\meinr\pipelines.py", line 21, in process_item
    html = requests.get(url=img,headers=spider.headers).content
  File "D:\Python\Python36\lib\site-packages\requests\api.py", line 72, in get
    return request('get', url, params=params, **kwargs)
  File "D:\Python\Python36\lib\site-packages\requests\api.py", line 58, in request
    return session.request(method=method, url=url, **kwargs)
  File "D:\Python\Python36\lib\site-packages\requests\sessions.py", line 508, in request
    resp = self.send(prep, **send_kwargs)
  File "D:\Python\Python36\lib\site-packages\requests\sessions.py", line 618, in send
    r = adapter.send(request, **kwargs)
  File "D:\Python\Python36\lib\site-packages\requests\adapters.py", line 490, in send
    raise ConnectionError(err, request=request)
requests.exceptions.ConnectionError: ('Connection aborted.', TimeoutError(10060, '由于连接方在一段时间后没有正确答复或连接的主机没有反应，连接尝试失败。', None, 10060, None))
2019-02-06 19:55:58 [scrapy.core.scraper] ERROR: Error processing {'img': 'http://img.tupianzj.com/uploads/allimg/180203/9-1P203130U0-50.jpg',
 'num': 3,
 'title': '美女模特Yumi尤美连体比基尼妩媚写真'}
Traceback (most recent call last):
  File "D:\Python\Python36\lib\site-packages\urllib3\connection.py", line 141, in _new_conn
    (self.host, self.port), self.timeout, **extra_kw)
  File "D:\Python\Python36\lib\site-packages\urllib3\util\connection.py", line 60, in create_connection
    for res in socket.getaddrinfo(host, port, family, socket.SOCK_STREAM):
  File "D:\Python\Python36\lib\socket.py", line 743, in getaddrinfo
    for res in _socket.getaddrinfo(host, port, family, type, proto, flags):
socket.gaierror: [Errno 11004] getaddrinfo failed

During handling of the above exception, another exception occurred:

Traceback (most recent call last):
  File "D:\Python\Python36\lib\site-packages\urllib3\connectionpool.py", line 601, in urlopen
    chunked=chunked)
  File "D:\Python\Python36\lib\site-packages\urllib3\connectionpool.py", line 357, in _make_request
    conn.request(method, url, **httplib_request_kw)
  File "D:\Python\Python36\lib\http\client.py", line 1239, in request
    self._send_request(method, url, body, headers, encode_chunked)
  File "D:\Python\Python36\lib\http\client.py", line 1285, in _send_request
    self.endheaders(body, encode_chunked=encode_chunked)
  File "D:\Python\Python36\lib\http\client.py", line 1234, in endheaders
    self._send_output(message_body, encode_chunked=encode_chunked)
  File "D:\Python\Python36\lib\http\client.py", line 1026, in _send_output
    self.send(msg)
  File "D:\Python\Python36\lib\http\client.py", line 964, in send
    self.connect()
  File "D:\Python\Python36\lib\site-packages\urllib3\connection.py", line 166, in connect
    conn = self._new_conn()
  File "D:\Python\Python36\lib\site-packages\urllib3\connection.py", line 150, in _new_conn
    self, "Failed to establish a new connection: %s" % e)
urllib3.exceptions.NewConnectionError: <urllib3.connection.HTTPConnection object at 0x000000000A6C2518>: Failed to establish a new connection: [Errno 11004] getaddrinfo failed

During handling of the above exception, another exception occurred:

Traceback (most recent call last):
  File "D:\Python\Python36\lib\site-packages\requests\adapters.py", line 440, in send
    timeout=timeout
  File "D:\Python\Python36\lib\site-packages\urllib3\connectionpool.py", line 639, in urlopen
    _stacktrace=sys.exc_info()[2])
  File "D:\Python\Python36\lib\site-packages\urllib3\util\retry.py", line 388, in increment
    raise MaxRetryError(_pool, url, error or ResponseError(cause))
urllib3.exceptions.MaxRetryError: HTTPConnectionPool(host='img.tupianzj.com', port=80): Max retries exceeded with url: /uploads/allimg/180203/9-1P203130U0-50.jpg (Caused by NewConnectionError('<urllib3.connection.HTTPConnection object at 0x000000000A6C2518>: Failed to establish a new connection: [Errno 11004] getaddrinfo failed',))

During handling of the above exception, another exception occurred:

Traceback (most recent call last):
  File "D:\Python\Python36\lib\site-packages\twisted\internet\defer.py", line 654, in _runCallbacks
    current.result = callback(current.result, *args, **kw)
  File "D:\spider_git\meinr\meinr\pipelines.py", line 21, in process_item
    html = requests.get(url=img,headers=spider.headers).content
  File "D:\Python\Python36\lib\site-packages\requests\api.py", line 72, in get
    return request('get', url, params=params, **kwargs)
  File "D:\Python\Python36\lib\site-packages\requests\api.py", line 58, in request
    return session.request(method=method, url=url, **kwargs)
  File "D:\Python\Python36\lib\site-packages\requests\sessions.py", line 508, in request
    resp = self.send(prep, **send_kwargs)
  File "D:\Python\Python36\lib\site-packages\requests\sessions.py", line 618, in send
    r = adapter.send(request, **kwargs)
  File "D:\Python\Python36\lib\site-packages\requests\adapters.py", line 508, in send
    raise ConnectionError(e, request=request)
requests.exceptions.ConnectionError: HTTPConnectionPool(host='img.tupianzj.com', port=80): Max retries exceeded with url: /uploads/allimg/180203/9-1P203130U0-50.jpg (Caused by NewConnectionError('<urllib3.connection.HTTPConnection object at 0x000000000A6C2518>: Failed to establish a new connection: [Errno 11004] getaddrinfo failed',))
2019-02-06 19:55:58 [scrapy.spidermiddlewares.httperror] INFO: Ignoring response <404 http://m.tupianzj.com/meinv/20180203/155849_1.html>: HTTP status code is not handled or not allowed
2019-02-06 19:56:11 [scrapy.core.scraper] ERROR: Error processing {'img': 'http://img.tupianzj.com/uploads/allimg/180203/9-1P203133R3.jpg',
 'num': 5,
 'title': '韩国萌妹子超短包臀裙大秀惹火曲线身材'}
Traceback (most recent call last):
  File "D:\Python\Python36\lib\site-packages\urllib3\connection.py", line 141, in _new_conn
    (self.host, self.port), self.timeout, **extra_kw)
  File "D:\Python\Python36\lib\site-packages\urllib3\util\connection.py", line 60, in create_connection
    for res in socket.getaddrinfo(host, port, family, socket.SOCK_STREAM):
  File "D:\Python\Python36\lib\socket.py", line 743, in getaddrinfo
    for res in _socket.getaddrinfo(host, port, family, type, proto, flags):
socket.gaierror: [Errno 11004] getaddrinfo failed

During handling of the above exception, another exception occurred:

Traceback (most recent call last):
  File "D:\Python\Python36\lib\site-packages\urllib3\connectionpool.py", line 601, in urlopen
    chunked=chunked)
  File "D:\Python\Python36\lib\site-packages\urllib3\connectionpool.py", line 357, in _make_request
    conn.request(method, url, **httplib_request_kw)
  File "D:\Python\Python36\lib\http\client.py", line 1239, in request
    self._send_request(method, url, body, headers, encode_chunked)
  File "D:\Python\Python36\lib\http\client.py", line 1285, in _send_request
    self.endheaders(body, encode_chunked=encode_chunked)
  File "D:\Python\Python36\lib\http\client.py", line 1234, in endheaders
    self._send_output(message_body, encode_chunked=encode_chunked)
  File "D:\Python\Python36\lib\http\client.py", line 1026, in _send_output
    self.send(msg)
  File "D:\Python\Python36\lib\http\client.py", line 964, in send
    self.connect()
  File "D:\Python\Python36\lib\site-packages\urllib3\connection.py", line 166, in connect
    conn = self._new_conn()
  File "D:\Python\Python36\lib\site-packages\urllib3\connection.py", line 150, in _new_conn
    self, "Failed to establish a new connection: %s" % e)
urllib3.exceptions.NewConnectionError: <urllib3.connection.HTTPConnection object at 0x000000000AA7F908>: Failed to establish a new connection: [Errno 11004] getaddrinfo failed

During handling of the above exception, another exception occurred:

Traceback (most recent call last):
  File "D:\Python\Python36\lib\site-packages\requests\adapters.py", line 440, in send
    timeout=timeout
  File "D:\Python\Python36\lib\site-packages\urllib3\connectionpool.py", line 639, in urlopen
    _stacktrace=sys.exc_info()[2])
  File "D:\Python\Python36\lib\site-packages\urllib3\util\retry.py", line 388, in increment
    raise MaxRetryError(_pool, url, error or ResponseError(cause))
urllib3.exceptions.MaxRetryError: HTTPConnectionPool(host='img.tupianzj.com', port=80): Max retries exceeded with url: /uploads/allimg/180203/9-1P203133R3.jpg (Caused by NewConnectionError('<urllib3.connection.HTTPConnection object at 0x000000000AA7F908>: Failed to establish a new connection: [Errno 11004] getaddrinfo failed',))

During handling of the above exception, another exception occurred:

Traceback (most recent call last):
  File "D:\Python\Python36\lib\site-packages\twisted\internet\defer.py", line 654, in _runCallbacks
    current.result = callback(current.result, *args, **kw)
  File "D:\spider_git\meinr\meinr\pipelines.py", line 21, in process_item
    html = requests.get(url=img,headers=spider.headers).content
  File "D:\Python\Python36\lib\site-packages\requests\api.py", line 72, in get
    return request('get', url, params=params, **kwargs)
  File "D:\Python\Python36\lib\site-packages\requests\api.py", line 58, in request
    return session.request(method=method, url=url, **kwargs)
  File "D:\Python\Python36\lib\site-packages\requests\sessions.py", line 508, in request
    resp = self.send(prep, **send_kwargs)
  File "D:\Python\Python36\lib\site-packages\requests\sessions.py", line 618, in send
    r = adapter.send(request, **kwargs)
  File "D:\Python\Python36\lib\site-packages\requests\adapters.py", line 508, in send
    raise ConnectionError(e, request=request)
requests.exceptions.ConnectionError: HTTPConnectionPool(host='img.tupianzj.com', port=80): Max retries exceeded with url: /uploads/allimg/180203/9-1P203133R3.jpg (Caused by NewConnectionError('<urllib3.connection.HTTPConnection object at 0x000000000AA7F908>: Failed to establish a new connection: [Errno 11004] getaddrinfo failed',))
